Workbook

Sheet Faturamento Geral 2025
A1: Indicadores | B1: Leads | E1: Nº Vendas | H1: Faturamento | L1: Taxa Conversão | O1: Ticket Médio
A2: Data | B2: Realizado | C2: Meta | D2: Gap | E2: Realizado | F2: Meta | G2: Gap | H2: Realizado | I2: Meta | J2: Gap | K2: % atingimento | L2: Realizado | M2: Meta | N2: Gap | O2: Realizado | P2: Meta | Q2: Gap
A3: 2025
A4: Setembro | B4: ='Recompra - 09'!B4+'Compra - 09 '!B4 -> 4310 | C4: ='Recompra - 09'!C4+'Compra - 09 '!C4 -> 6120 | D4: =B4-C4 -> -1810 | E4: ='Recompra - 09'!E4+'Compra - 09 '!E4 -> 1177 | F4: ='Recompra - 09'!F4+'Compra - 09 '!F4 -> 1458 | G4: =F4-E4 -> 281 | H4: ='Compra - 09 '!H4+'Recompra - 09'!H4 -> 305877.8 | I4: ='Compra - 09 '!I4+'Recompra - 09'!I4 -> 357900 | J4: =H4-I4 -> -52022.2 | L4: =E4/B4 -> 0.27308585 | M4: 0.4 | N4: =L4-M4 -> -0.12691415 | O4: =H4/E4 -> 259.87918 | P4: 250 | Q4: =O4-P4 -> 9.8791844
A5: Outubro | B5: ='Recompra - 10'!B4+'Compra - 10 '!B4 -> 4018 | C5: ='Recompra - 10'!C4+'Compra - 10 '!C4 -> 6030 | D5: =B5-C5 -> -2012 | E5: ='Recompra - 10'!E4+'Compra - 10 '!E4 -> 1220 | F5: ='Recompra - 10'!F4+'Compra - 10 '!F4 -> 1431 | G5: =F5-E5 -> 211 | H5: ='Compra - 09 '!H5+'Recompra - 09'!H5 -> 151018.97 | I5: 550000 | J5: =H5-I5 -> -398981.03 | L5: =E5/B5 -> 0.30363365 | M5: 0.4 | N5: =L5-M5 -> -0.096366351 | O5: =H5/E5 -> 123.78604 | P5: 250 | Q5: =O5-P5 -> -126.21396
A6: Novembro | B6: ='Recompra - 11'!B4+'Compra - 11'!B4 -> 2986 | C6: ='Recompra - 10'!C5+'Compra - 10 '!C5 -> 2310 | D6: =B6-C6 -> 676 | E6: ='Recompra - 11'!E4+'Compra - 11'!E4 -> 1446 | F6: ='Recompra - 10'!F5+'Compra - 10 '!F5 -> 693 | G6: =E6-F6 -> 753 | H6: 414625.26 | I6: 510000 | J6: =H6-I6 -> -95374.74 | K6: =H6/I6 -> 0.81299071 | L6: =E6/B6 -> 0.48425988 | M6: 0.4 | N6: =L6-M6 -> 0.084259879 | O6: =H6/E6 -> 286.73946 | P6: 250 | Q6: =O6-P6 -> 36.739461
A7: Dezembro | B7: ='Recompra - 12'!B4+'Compra - 12'!B4 -> 1908 | C7: ='Recompra - 12'!C4+'Compra - 12'!C4 -> 6061 | D7: =B7-C7 -> -4153 | E7: ='Recompra - 12'!E4+'Compra - 12'!E4 -> 1131 | F7: ='Recompra - 12'!F4+'Compra - 12'!F4 -> 2616.1 | G7: =E7-F7 -> -1485.1 | H7: 287241.46 | I7: 510000 | J7: =H7-I7 -> -222758.54 | K7: =H7/I7 -> 0.56321855 | L7: =E7/B7 -> 0.5927673 | M7: 0.4 | N7: =L7-M7 -> 0.1927673 | O7: =H7/E7 -> 253.97123 | P7: 250 | Q7: =O7-P7 -> 3.971229

Sheet GERAL - 12
C1: DEZEMBRO
C2: 510000 | D2: 24150 | E2: 8000
A4: DATA | B4: DIA | C4: VALOR | D4: QNTD FORMULAS | E4: TKT MEDIO | F4: SALDO DO DIA | G4: SALDO GERAL
A5: 45992 | B5: SEG | C5: 19973.4 | D5: 82 | E5: =C5/D5 -> 243.57805 | F5: =C5-D2 -> -4176.6 | G5: =F5 -> -4176.6
A6: 45993 | B6: TER | C6: 24491.75 | D6: 85 | E6: =C6/D6 -> 288.13824 | F6: =C6-D2 -> 341.75 | G6: =F6+G5 -> -3834.85
A7: 45994 | B7: QUA | C7: 13334.3 | D7: 66 | E7: =C7/D7 -> 202.03485 | F7: =C7-D2 -> -10815.7 | G7: =F7+G6 -> -14650.55
A8: 45995 | B8: QUI | C8: 13138.01 | D8: 63 | E8: =C8/D8 -> 208.53984 | F8: =C8-D2 -> -11011.99 | G8: =F8+G7 -> -25662.54
A9: 45996 | B9: SEX | C9: 18642.39 | D9: 78 | E9: =C9/D9 -> 239.005 | F9: =C9-D2 -> -5507.61 | G9: =F9+G8 -> -31170.15
A10: 45997 | B10: SAB | C10: 4916.29 | D10: 30 | E10: =C10/D10 -> 163.87633 | F10: =C10-E2 -> -3083.71 | G10: =F10+G9 -> -34253.86
A11: 45998 | B11: DOM | G11: =F11+G10 -> -34253.86
A12: 45999 | B12: SEG | C12: 18033.93 | D12: 79 | E12: =C12/D12 -> 228.27759 | F12: =C12-D2 -> -6116.07 | G12: =F12+G11 -> -40369.93
A13: 46000 | B13: TER | C13: 18356.73 | D13: 76 | E13: =C13/D13 -> 241.53592 | F13: =C13-D2 -> -5793.27 | G13: =F13+G12 -> -46163.2
A14: 46001 | B14: QUA | C14: 20158.71 | D14: 84 | E14: =C14/D14 -> 239.98464 | F14: =C14-D2 -> -3991.29 | G14: =F14+G13 -> -50154.49
A15: 46002 | B15: QUI | C15: 16635.79 | D15: 86 | E15: =C15/D15 -> 193.43942 | F15: =C15-D2 -> -7514.21 | G15: =F15+G14 -> -57668.7
A16: 46003 | B16: SEX | C16: 15007.88 | D16: 70 | E16: =C16/D16 -> 214.39829 | F16: =C16-D2 -> -9142.12 | G16: =F16+G15 -> -66810.82
A17: 46004 | B17: SAB | C17: 5586.66 | D17: 25 | E17: =C17/D17 -> 223.4664 | F17: =C17-E2 -> -2413.34 | G17: =F17+G16 -> -69224.16
A18: 46005 | B18: DOM | G18: =F18+G17 -> -69224.16
A19: 46006 | B19: SEG | C19: 16104.86 | D19: 80 | E19: =C19/D19 -> 201.31075 | F19: =C19-D2 -> -8045.14 | G19: =F19+G18 -> -77269.3
A20: 46007 | B20: TER | C20: 18870.71 | D20: 77 | E20: =C20/D20 -> 245.07416 | F20: =C20-D2 -> -5279.29 | G20: =F20+G19 -> -82548.59
A21: 46008 | B21: QUA | C21: 15490.14 | D21: 59 | E21: =C21/D21 -> 262.54475 | F21: =C21-D2 -> -8659.86 | G21: =F21+G20 -> -91208.45
A22: 46009 | B22: QUI | C22: 15554.44 | D22: 66 | E22: =C22/D22 -> 235.67333 | F22: =C22-D2 -> -8595.56 | G22: =F22+G21 -> -99804.01
A23: 46010 | B23: SEX | C23: 9613.42 | D23: 50 | E23: =C23/D23 -> 192.2684 | F23: =C23-D2 -> -14536.58 | G23: =F23+G22 -> -114340.59
A24: 46011 | B24: SAB | C24: 5251.1 | D24: 24 | E24: =C24/D24 -> 218.79583 | F24: =C24-E2 -> -2748.9 | G24: =F24+G23 -> -117089.49
A25: 46012 | B25: DOM | G25: =F25+G24 -> -117089.49
A26: 46013 | B26: SEG | C26: 18080.95 | D26: 72 | E26: =C26/D26 -> 251.12431 | F26: =C26-D2 -> -6069.05 | G26: =F26+G25 -> -123158.54
A27: 46014 | B27: TER | E27: =C27/D27 -> #DIV/0! | F27: =C27-D2 -> -24150 | G27: =F27+G26 -> -147308.54
A28: 46015 | B28: QUA | E28: =C28/D28 -> #DIV/0! | F28: =C28-D2 -> -24150 | G28: =F28+G27 -> -171458.54
A29: 46016 | B29: QUI | E29: =C29/D29 -> #DIV/0! | G29: =F29+G28 -> -171458.54
A30: 46017 | B30: SEX | E30: =C30/D30 -> #DIV/0! | F30: =C30-D2 -> -24150 | G30: =F30+G28 -> -195608.54
A31: 46018 | B31: SAB | E31: =C31/D31 -> #DIV/0! | F31: =C31-E2 -> -8000 | G31: =F31+G30 -> -203608.54
A32: 46019 | B32: DOM | G32: =F32+G31 -> -203608.54
A33: 46020 | B33: SEG | E33: =C33/D33 -> #DIV/0! | F33: =C33-D2 -> -24150 | G33: =F33+G32 -> -227758.54
A34: 46021 | B34: TER | E34: =C34/D34 -> #DIV/0! | F34: =C34-D2 -> -24150 | G34: =F34+G33 -> -251908.54
A35: 46022 | B35: QUA | E35: =C35/D35 -> #DIV/0! | G35: =F35+G34 -> -251908.54
A37: TOTAL | C37: =SUM(C5:C35) -> 287241.46 | D37: =SUM(D5:D35) -> 1252 | E37: =C37/D37 -> 229.42609

Sheet Compra - 11
A1: Indicadores | B1: Leads | E1: Nº Vendas | H1: Faturamento | K1: Taxa Conversão | N1: Ticket Médio
A2: Data | B2: Realizado | C2: Meta | D2: Gap | E2: Realizado 2 | F2: Meta 2 | G2: Gap 2 | H2: Realizado 3 | I2: Meta 3 | J2: Gap 3 | K2: Realizado 4 | L2: Meta 4 | M2: Gap 4 | N2: Realizado 5 | O2: Meta 5 | P2: Gap 5
A3: 2025
A4: Novembro | B4: =B5+B36+B67+B98 -> 1647 | C4: =C5+C36 -> 2125 | D4: =D5 -> -763 | E4: =E5+E36+E67+E98 -> 619 | F4: =F5 -> 511.5 | G4: =G5 -> -132 | H4: =H5+H36+H67+H98 -> 149212.54 | I4: =I5+I36+I67+I98 -> 170000 | J4: =J5 -> -17438.89 | K4: =E4/B4 -> 0.37583485 | L4: =L5 -> 0.3 | M4: =K4-L4 -> 0.075834851 | N4: =N5 -> 297.3816 | O4: =O5 -> 250 | P4: =P5 -> 47.381598
A5: Thalia | B5: =SUM(B6:B35) -> 942 | C5: =SUM(C6:C35) -> 1705 | D5: =SUM(D6:D35) -> -763 | E5: =SUM(E6:E35) -> 244 | F5: =C5*30% -> 511.5 | G5: =SUM(G6:G35) -> -132 | H5: =SUM(H6:H35) -> 72561.11 | I5: =SUM(I6:I35) -> 90000 | J5: =SUM(J6:J35) -> -17438.89 | K5: =E5/B5 -> 0.25902335 | L5: 0.3 | M5: =K5-L5 -> -0.040976645 | N5: =IFERROR(H5/E5,"") -> 297.3816 | O5: 250 | P5: =N5-O5 -> 47.381598
A6: 45962 | B6: 10 | C6: 29 | D6: =B6-C6 -> -19 | E6: 4 | F6: 9 | G6: =E6-F6 -> -5 | H6: 1678.81 | I6: 0 | J6: =H6-I6 -> 1678.81 | K6: =E6/B6 -> 0.4 | L6: 0.3 | M6: =L6-K6 -> -0.1 | N6: =IFERROR(H6/E6,"") -> 419.7025 | O6: 250 | P6: =N6-O6 -> 169.7025 | R6: THALIA
A7: 45963 | B7: 0 | C7: 0 | D7: =B7-C7 -> 0 | E7: 0 | F7: 0 | G7: =E7-F7 -> 0 | H7: 0 | I7: 0 | J7: =H7-I7 -> 0 | K7: =E7/B7 -> #DIV/0! | L7: 0.3 | M7: =L7-K7 -> #DIV/0! | N7: =IFERROR(H7/E7,"") | O7: 250 | P7: =N7-O7 -> -250 | R7: Outubro
A8: 45964 | B8: 57 | C8: 78 | D8: =B8-C8 -> -21 | E8: 18 | F8: 17 | G8: =E8-F8 -> 1 | H8: 7938.59 | I8: 4500 | J8: =H8-I8 -> 3438.59 | K8: =E8/B8 -> 0.31578947 | L8: 0.3 | M8: =L8-K8 -> -0.015789474 | N8: =IFERROR(H8/E8,"") -> 441.03278 | O8: 250 | P8: =N8-O8 -> 191.03278 | R8: Meta | S8: 90000
A9: 45965 | B9: 57 | C9: 78 | D9: =B9-C9 -> -21 | E9: 15 | F9: 17 | G9: =E9-F9 -> -2 | H9: 4336.09 | I9: 4500 | J9: =H9-I9 -> -163.91 | K9: =E9/B9 -> 0.26315789 | L9: 0.3 | M9: =L9-K9 -> 0.036842105 | N9: =IFERROR(H9/E9,"") -> 289.07267 | O9: 250 | P9: =N9-O9 -> 39.072667 | R9: Meta x Dia | S9: =S8/30 -> 3000
A10: 45966 | B10: 39 | C10: 78 | D10: =B10-C10 -> -39 | E10: 12 | F10: 17 | G10: =E10-F10 -> -5 | H10: 2905.36 | I10: 4500 | J10: =H10-I10 -> -1594.64 | K10: =E10/B10 -> 0.30769231 | L10: 0.3 | M10: =L10-K10 -> -0.0076923077 | N10: =IFERROR(H10/E10,"") -> 242.11333 | O10: 250 | P10: =N10-O10 -> -7.8866667 | R10: Meta x Dia Útil | S10: =S8/20 -> 4500
A11: 45967 | B11: 39 | C11: 78 | D11: =B11-C11 -> -39 | E11: 15 | F11: 17 | G11: =E11-F11 -> -2 | H11: 7649.02 | I11: 4500 | J11: =H11-I11 -> 3149.02 | K11: =E11/B11 -> 0.38461538 | L11: 0.3 | M11: =L11-K11 -> -0.084615385 | N11: =IFERROR(H11/E11,"") -> 509.93467 | O11: 250 | P11: =N11-O11 -> 259.93467 | R11: Realizado | S11: =H5 -> 72561.11 | T11: =S8-S11 -> 17438.89
A12: 45968 | B12: 43 | C12: 78 | D12: =B12-C12 -> -35 | E12: 8 | F12: 17 | H12: 1900.89 | I12: 4500 | J12: =H12-I12 -> -2599.11 | K12: =E12/B12 -> 0.18604651 | N12: =IFERROR(H12/E12,"") -> 237.61125 | P12: =N12-O12 -> 237.61125 | R12: % da Meta | S12: =S11/S8 -> 0.80623456
A13: 45969 | B13: 19 | C13: 29 | D13: =B13-C13 -> -10 | E13: 2 | F13: 9 | G13: =E13-F13 -> -7 | H13: 1415 | I13: 0 | J13: =H13-I13 -> 1415 | K13: =E13/B13 -> 0.10526316 | L13: 0.3 | M13: =L13-K13 -> 0.19473684 | N13: =IFERROR(H13/E13,"") -> 707.5 | O13: 250 | P13: =N13-O13 -> 457.5 | R13: Dias Útil Restante | S13: 1
A14: 45970 | B14: 0 | C14: 0 | D14: =B14-C14 -> 0 | E14: 0 | F14: 0 | G14: =E14-F14 -> 0 | H14: 0 | I14: 0 | J14: =H14-I14 -> 0 | K14: =E14/B14 -> #DIV/0! | L14: 0.3 | M14: =L14-K14 -> #DIV/0! | N14: =IFERROR(H14/E14,"") | O14: 250 | P14: =N14-O14 -> -250 | R14: Meta dia Acumulado | S14: =(S8-S11)/S13 -> 17438.89
A15: 45971 | B15: 36 | C15: 78 | D15: =B15-C15 -> -42 | E15: 8 | F15: 17 | G15: =E15-F15 -> -9 | H15: 2512.07 | I15: 4500 | J15: =H15-I15 -> -1987.93 | K15: =E15/B15 -> 0.22222222 | L15: 0.3 | M15: =L15-K15 -> 0.077777778 | N15: =IFERROR(H15/E15,"") -> 314.00875 | O15: 250 | P15: =N15-O15 -> 64.00875 | R15: Ticket Médio | S15: =N5 -> 297.3816
A16: 45972 | B16: 67 | C16: 78 | D16: =B16-C16 -> -11 | E16: 17 | F16: 17 | G16: =E16-F16 -> 0 | H16: 3772.71 | I16: 4500 | J16: =H16-I16 -> -727.29 | K16: =E16/B16 -> 0.25373134 | L16: 0.3 | M16: =L16-K16 -> 0.046268657 | N16: =IFERROR(H16/E16,"") -> 221.92412 | O16: 250 | P16: =N16-O16 -> -28.075882 | R16: Nº Leads | S16: =B5 -> 942
A17: 45973 | B17: 38 | C17: 78 | D17: =B17-C17 -> -40 | E17: 15 | F17: 17 | G17: =E17-F17 -> -2 | H17: 4546.6 | I17: 4500 | J17: =H17-I17 -> 46.6 | K17: =E17/B17 -> 0.39473684 | L17: 0.3 | M17: =L17-K17 -> -0.094736842 | N17: =IFERROR(H17/E17,"") -> 303.10667 | O17: 250 | P17: =N17-O17 -> 53.106667 | R17: Nº Vendas | S17: =E5 -> 244
A18: 45974 | B18: 68 | C18: 78 | D18: =B18-C18 -> -10 | E18: 10 | F18: 17 | G18: =E18-F18 -> -7 | H18: 2625.99 | I18: 4500 | J18: =H18-I18 -> -1874.01 | K18: =E18/B18 -> 0.14705882 | L18: 0.3 | M18: =L18-K18 -> 0.15294118 | N18: =IFERROR(H18/E18,"") -> 262.599 | O18: 250 | P18: =N18-O18 -> 12.599 | R18: Taxa Conversão | S18: =E5/B5 -> 0.25902335
A19: 45975 | B19: 38 | C19: 78 | D19: =B19-C19 -> -40 | E19: 17 | F19: 17 | G19: =E19-F19 -> 0 | H19: 2875.28 | I19: 4500 | J19: =H19-I19 -> -1624.72 | K19: =E19/B19 -> 0.44736842 | L19: 0.3 | M19: =L19-K19 -> -0.14736842 | N19: =IFERROR(H19/E19,"") -> 169.13412 | O19: 250 | P19: =N19-O19 -> -80.865882
A20: 45976 | B20: 11 | C20: 29 | D20: =B20-C20 -> -18 | E20: 3 | F20: 9 | G20: =E20-F20 -> -6 | H20: 797.07 | I20: 0 | J20: =H20-I20 -> 797.07 | K20: =E20/B20 -> 0.27272727 | L20: 0.3 | M20: =L20-K20 -> 0.027272727 | N20: =IFERROR(H20/E20,"") -> 265.69 | O20: 250 | P20: =N20-O20 -> 15.69
A21: 45977 | B21: 0 | C21: 0 | D21: =B21-C21 -> 0 | E21: 0 | F21: 0 | G21: =E21-F21 -> 0 | H21: 0 | I21: 0 | J21: =H21-I21 -> 0 | K21: =E21/B21 -> #DIV/0! | L21: 0.3 | M21: =L21-K21 -> #DIV/0! | N21: =IFERROR(H21/E21,"") | O21: 250 | P21: =N21-O21 -> -250
A22: 45978 | B22: 48 | C22: 78 | D22: =B22-C22 -> -30 | E22: 10 | F22: 17 | G22: =E22-F22 -> -7 | H22: 1570.83 | I22: 4500 | J22: =H22-I22 -> -2929.17 | K22: =E22/B22 -> 0.20833333 | L22: 0.3 | M22: =L22-K22 -> 0.091666667 | N22: =IFERROR(H22/E22,"") -> 157.083 | O22: 250 | P22: =N22-O22 -> -92.917
A23: 45979 | B23: 49 | C23: 78 | D23: =B23-C23 -> -29 | E23: 13 | F23: 17 | G23: =E23-F23 -> -4 | H23: 1614.8 | I23: 4500 | J23: =H23-I23 -> -2885.2 | K23: =E23/B23 -> 0.26530612 | L23: 0.3 | M23: =L23-K23 -> 0.034693878 | N23: =IFERROR(H23/E23,"") -> 124.21538 | O23: 250 | P23: =N23-O23 -> -125.78462
A24: 45980 | B24: 47 | C24: 78 | D24: =B24-C24 -> -31 | E24: 9 | F24: 17 | G24: =E24-F24 -> -8 | H24: 3508.6 | I24: 4500 | J24: =H24-I24 -> -991.4 | K24: =E24/B24 -> 0.19148936 | L24: 0.3 | M24: =L24-K24 -> 0.10851064 | N24: =IFERROR(H24/E24,"") -> 389.84444 | O24: 250 | P24: =N24-O24 -> 139.84444
A25: 45981 | B25: 11 | C25: 78 | D25: =B25-C25 -> -67 | E25: 2 | F25: 17 | G25: =E25-F25 -> -15 | H25: 213.56 | I25: 4500 | J25: =H25-I25 -> -4286.44 | K25: =E25/B25 -> 0.18181818 | L25: 0.3 | M25: =L25-K25 -> 0.11818182 | N25: =IFERROR(H25/E25,"") -> 106.78 | O25: 250 | P25: =N25-O25 -> -143.22
A26: 45982 | B26: 43 | C26: 78 | D26: =B26-C26 -> -35 | E26: 9 | F26: 17 | G26: =E26-F26 -> -8 | H26: 3036.53 | I26: 4500 | J26: =H26-I26 -> -1463.47 | K26: =E26/B26 -> 0.20930233 | L26: 0.3 | M26: =L26-K26 -> 0.090697674 | N26: =IFERROR(H26/E26,"") -> 337.39222 | O26: 250 | P26: =N26-O26 -> 87.392222
A27: 45983 | B27: 17 | C27: 29 | D27: =B27-C27 -> -12 | E27: 2 | F27: 9 | G27: =E27-F27 -> -7 | H27: 505.61 | I27: 0 | J27: =H27-I27 -> 505.61 | K27: =E27/B27 -> 0.11764706 | L27: 0.3 | M27: =L27-K27 -> 0.18235294 | N27: =IFERROR(H27/E27,"") -> 252.805 | O27: 250 | P27: =N27-O27 -> 2.805
A28: 45984 | B28: 0 | C28: 0 | D28: =B28-C28 -> 0 | E28: 0 | F28: 0 | G28: =E28-F28 -> 0 | H28: 0 | I28: 0 | J28: =H28-I28 -> 0 | K28: =E28/B28 -> #DIV/0! | L28: 0.3 | M28: =L28-K28 -> #DIV/0! | N28: =IFERROR(H28/E28,"") | O28: 250 | P28: =N28-O28 -> -250
A29: 45985 | B29: 49 | C29: 78 | D29: =B29-C29 -> -29 | E29: 8 | F29: 17 | G29: =E29-F29 -> -9 | H29: 2064.32 | I29: 4500 | J29: =H29-I29 -> -2435.68 | K29: =E29/B29 -> 0.16326531 | L29: 0.3 | M29: =L29-K29 -> 0.13673469 | N29: =IFERROR(H29/E29,"") -> 258.04 | O29: 250 | P29: =N29-O29 -> 8.04
A30: 45986 | B30: 32 | C30: 78 | D30: =B30-C30 -> -46 | E30: 10 | F30: 17 | G30: =E30-F30 -> -7 | H30: 3054.12 | I30: 4500 | J30: =H30-I30 -> -1445.88 | K30: =E30/B30 -> 0.3125 | L30: 0.3 | M30: =L30-K30 -> -0.0125 | N30: =IFERROR(H30/E30,"") -> 305.412 | O30: 250 | P30: =N30-O30 -> 55.412
... A35: 45991 | B35: 0 | C35: 0 | D35: =B35-C35 -> 0 | E35: 0 | F35: 0 | G35: =E35-F35 -> 0 | H35: 0 | I35: 0 | J35: =H35-I35 -> 0 | K35: =E35/B35 -> #DIV/0! | L35: 0.3 | M35: =L35-K35 -> #DIV/0! | N35: =IFERROR(H35/E35,"") | O35: 250 | P35: =N35-O35 -> -250
A36: Mirian | B36: =SUM(B37:B66) -> 416 | C36: =SUM(C37:C66) -> 420 | D36: =SUM(D37:D66) -> -4 | E36: =SUM(E37:E66) -> 310 | F36: =SUM(F37:F66) -> 185 | G36: =SUM(G37:G66) -> 125 | H36: =SUM(H37:H66) -> 59067.79 | I36: =SUM(I37:I66) -> 50000 | J36: =H36-I36 -> 9067.79 | K36: =E36/B36 -> 0.74519231 | L36: 0.5 | M36: =K36-L36 -> 0.24519231 | N36: =IFERROR(H36/E36,"") -> 190.54126 | O36: =O37 -> 250 | P36: =N36-O36 -> -59.458742
A37: 45962 | B37: 3 | C37: 4 | D37: =B37-C37 -> -1 | E37: 3 | F37: 5 | G37: =E37-F37 -> -2 | H37: 782.58 | I37: 0 | J37: =H37-I37 -> 782.58 | K37: =IFERROR(E37/B37,"") -> 1 | L37: 0 | M37: =L37-K37 -> -1 | N37: =IFERROR(H37/E37,"") -> 260.86 | O37: 250 | P37: =N37-O37 -> 10.86 | R37: MIRIAN
A38: 45963 | B38: 0 | C38: 0 | D38: =B38-C38 -> 0 | E38: 0 | F38: 0 | G38: =E38-F38 -> 0 | H38: 0 | I38: 0 | J38: =H38-I38 -> 0 | K38: =IFERROR(E38/B38,"") | L38: 0 | M38: =L38-K38 -> 0 | N38: =IFERROR(H38/E38,"") | O38: 250 | P38: =N38-O38 -> -250 | R38: Outubro
A39: 45964 | B39: 15 | C39: 20 | D39: =B39-C39 -> -5 | E39: 13 | F39: 8 | G39: =E39-F39 -> 5 | H39: 5284.61 | I39: 2500 | J39: =H39-I39 -> 2784.61 | K39: =IFERROR(E39/B39,"") -> 0.86666667 | L39: 0.5 | M39: =L39-K39 -> -0.36666667 | N39: =IFERROR(H39/E39,"") -> 406.50846 | O39: 250 | P39: =N39-O39 -> 156.50846 | R39: Meta | S39: 50000
A40: 45965 | B40: 25 | C40: 20 | D40: =B40-C40 -> 5 | E40: 18 | F40: 8 | G40: =E40-F40 -> 10 | H40: 2291.07 | I40: 2500 | J40: =H40-I40 -> -208.93 | K40: =IFERROR(E40/B40,"") -> 0.72 | L40: 0.5 | M40: =L40-K40 -> -0.22 | N40: =IFERROR(H40/E40,"") -> 127.28167 | O40: 250 | P40: =N40-O40 -> -122.71833 | R40: Meta x Dia | S40: =S39/30 -> 1666.6667
A41: 45966 | B41: 15 | C41: 20 | D41: =B41-C41 -> -5 | E41: 12 | F41: 8 | G41: =E41-F41 -> 4 | H41: 1648.38 | I41: 2500 | J41: =H41-I41 -> -851.62 | K41: =IFERROR(E41/B41,"") -> 0.8 | L41: 0.5 | M41: =L41-K41 -> -0.3 | N41: =IFERROR(H41/E41,"") -> 137.365 | O41: 250 | P41: =N41-O41 -> -112.635 | R41: Meta x Dia Útil | S41: =S39/20 -> 2500
A42: 45967 | B42: 22 | C42: 20 | D42: =B42-C42 -> 2 | E42: 13 | F42: 8 | G42: =E42-F42 -> 5 | H42: 2782.19 | I42: 2500 | J42: =H42-I42 -> 282.19 | K42: =IFERROR(E42/B42,"") -> 0.59090909 | L42: 0.5 | M42: =L42-K42 -> -0.090909091 | N42: =IFERROR(H42/E42,"") -> 214.01462 | O42: 250 | P42: =N42-O42 -> -35.985385 | R42: Realizado | S42: =H36 -> 59067.79
A43: 45968 | B43: 14 | C43: 20 | D43: =B43-C43 -> -6 | E43: 8 | F43: 8 | H43: 927.61 | I43: 2500 | J43: =H43-I43 -> -1572.39 | K43: =IFERROR(E43/B43,"") -> 0.57142857 | L43: 0.5 | M43: =L43-K43 -> -0.071428571 | N43: =IFERROR(H43/E43,"") -> 115.95125 | P43: =N43-O43 -> 115.95125 | R43: % da Meta | S43: =S42/S39 -> 1.1813558
A44: 45969 | B44: 24 | C44: 4 | D44: =B44-C44 -> 20 | E44: 12 | F44: 5 | G44: =E44-F44 -> 7 | H44: 2527.83 | I44: 0 | J44: =H44-I44 -> 2527.83 | K44: =IFERROR(E44/B44,"") -> 0.5 | L44: 0 | M44: =L44-K44 -> -0.5 | N44: =IFERROR(H44/E44,"") -> 210.6525 | O44: 250 | P44: =N44-O44 -> -39.3475 | R44: Dias Útil Restante | S44: 2
...

Sheet Compra - 12
A1: Indicadores | B1: Leads | E1: Nº Vendas | H1: Faturamento | K1: Taxa Conversão | N1: Ticket Médio
A2: Data | B2: Realizado | C2: Meta | D2: Gap | E2: Realizado 2 | F2: Meta 2 | G2: Gap 2 | H2: Realizado 3 | I2: Meta 3 | J2: Gap 3 | K2: Realizado 4 | L2: Meta 4 | M2: Gap 4 | N2: Realizado 5 | O2: Meta 5 | P2: Gap 5
A3: 2025
A4: Dezembro | B4: =B5+B37+B69+B101 -> 1058 | C4: =C5+C37+C69+C101 -> 3243 | D4: =D5 -> -538 | E4: =E5+E37+E69+E101 -> 440 | F4: =F5+F37+F69+F101 -> 1078.1 | G4: =G5 -> -75 | H4: =H5+H37+H69+H101 -> 105326.67 | I4: =I5+I37+I69+I101 -> 239750 | J4: =J5 -> -35239.32 | K4: =E4/B4 -> 0.41587902 | L4: =L5 -> 0.3 | M4: =K4-L4 -> 0.11587902 | N4: =AVERAGE(N5:N101) -> 253.21381 | O4: =O5 -> 250 | P4: =P5 -> -9.0261818
A5: Thalia | B5: =SUM(B6:B35) -> 589 | C5: =SUM(C6:C36) -> 1127 | D5: =SUM(D6:D35) -> -538 | E5: =SUM(E6:E35) -> 165 | F5: =C5*30% -> 338.1 | G5: =SUM(G6:G35) -> -75 | H5: =SUM(H6:H35) -> 39760.68 | I5: =SUM(I6:I35) -> 75000 | J5: =SUM(J6:J35) -> -35239.32 | K5: =E5/B5 -> 0.28013582 | L5: 0.3 | M5: =K5-L5 -> -0.019864177 | N5: =IFERROR(H5/E5,"") -> 240.97382 | O5: 250 | P5: =N5-O5 -> -9.0261818
A6: 45992 | B6: 48 | C6: 49 | D6: =B6-C6 -> -1 | E6: 10 | F6: 12 | G6: =E6-F6 -> -2 | H6: 3379.78 | I6: 3750 | J6: =H6-I6 -> -370.22 | K6: =E6/B6 -> 0.20833333 | L6: 0.3 | M6: =L6-K6 -> 0.091666667 | N6: =IFERROR(H6/E6,"") -> 337.978 | O6: 250 | P6: =N6-O6 -> 87.978 | R6: THALIA
A7: 45993 | B7: 48 | C7: 49 | D7: =B7-C7 -> -1 | E7: 18 | F7: 12 | G7: =E7-F7 -> 6 | H7: 3484.06 | I7: 3750 | J7: =H7-I7 -> -265.94 | K7: =E7/B7 -> 0.375 | L7: 0.3 | M7: =L7-K7 -> -0.075 | N7: =IFERROR(H7/E7,"") -> 193.55889 | O7: 250 | P7: =N7-O7 -> -56.441111 | R7: DEZEMBRO
A8: 45994 | B8: 49 | C8: 49 | D8: =B8-C8 -> 0 | E8: 11 | F8: 12 | G8: =E8-F8 -> -1 | H8: 2051.6 | I8: 3750 | J8: =H8-I8 -> -1698.4 | K8: =E8/B8 -> 0.2244898 | L8: 0.3 | M8: =L8-K8 -> 0.075510204 | N8: =IFERROR(H8/E8,"") -> 186.50909 | O8: 250 | P8: =N8-O8 -> -63.490909 | R8: Meta | S8: 75000 | T8: =S8-S11 -> 35239.32
A9: 45995 | B9: 46 | C9: 49 | D9: =B9-C9 -> -3 | E9: 9 | F9: 12 | G9: =E9-F9 -> -3 | H9: 1786.24 | I9: 3750 | J9: =H9-I9 -> -1963.76 | K9: =E9/B9 -> 0.19565217 | L9: 0.3 | M9: =L9-K9 -> 0.10434783 | N9: =IFERROR(H9/E9,"") -> 198.47111 | O9: 250 | P9: =N9-O9 -> -51.528889 | R9: Meta x Dia | S9: =S8/30 -> 2500
A10: 45996 | B10: 56 | C10: 49 | D10: =B10-C10 -> 7 | E10: 12 | F10: 12 | G10: =E10-F10 -> 0 | H10: 2512.15 | I10: 3750 | J10: =H10-I10 -> -1237.85 | K10: =E10/B10 -> 0.21428571 | L10: 0.3 | M10: =L10-K10 -> 0.085714286 | N10: =IFERROR(H10/E10,"") -> 209.34583 | O10: 250 | P10: =N10-O10 -> -40.654167 | R10: Meta x Dia Útil | S10: =S8/20 -> 3750
A11: 45997 | B11: 9 | C11: 49 | D11: =B11-C11 -> -40 | E11: 7 | F11: 0 | G11: =E11-F11 -> 7 | H11: 611.96 | I11: 0 | J11: =H11-I11 -> 611.96 | K11: =E11/B11 -> 0.77777778 | L11: 0.3 | M11: =L11-K11 -> -0.47777778 | N11: =IFERROR(H11/E11,"") -> 87.422857 | O11: 250 | P11: =N11-O11 -> -162.57714 | R11: Realizado | S11: =H5 -> 39760.68
A12: 45998 | H12: 0 | R12: % da Meta | S12: =S11/S8 -> 0.5301424
A13: 45999 | B13: 36 | C13: 49 | D13: =B13-C13 -> -13 | E13: 8 | F13: 12 | G13: =E13-F13 -> -4 | H13: 2037.44 | I13: 3750 | J13: =H13-I13 -> -1712.56 | K13: =E13/B13 -> 0.22222222 | L13: 0.3 | M13: =L13-K13 -> 0.077777778 | N13: =IFERROR(H13/E13,"") -> 254.68 | O13: 250 | P13: =N13-O13 -> 4.68 | R13: Dias Útil Restante | S13: 4
A14: 46000 | B14: 34 | C14: 49 | D14: =B14-C14 -> -15 | E14: 11 | F14: 12 | G14: =E14-F14 -> -1 | H14: 3366.49 | I14: 3750 | J14: =H14-I14 -> -383.51 | K14: =E14/B14 -> 0.32352941 | L14: 0.3 | M14: =L14-K14 -> -0.023529412 | N14: =IFERROR(H14/E14,"") -> 306.04455 | O14: 250 | P14: =N14-O14 -> 56.044545 | R14: Meta dia Acumulado | S14: =(S8-S11)/S13 -> 8809.83
A15: 46001 | B15: 32 | C15: 49 | D15: =B15-C15 -> -17 | E15: 9 | F15: 12 | G15: =E15-F15 -> -3 | H15: 2473.49 | I15: 3750 | J15: =H15-I15 -> -1276.51 | K15: =E15/B15 -> 0.28125 | L15: 0.3 | M15: =L15-K15 -> 0.01875 | N15: =IFERROR(H15/E15,"") -> 274.83222 | O15: 250 | P15: =N15-O15 -> 24.832222 | R15: Ticket Médio | S15: =N5 -> 240.97382
A16: 46002 | B16: 31 | C16: 49 | D16: =B16-C16 -> -18 | E16: 13 | F16: 12 | G16: =E16-F16 -> 1 | H16: 2151.71 | I16: 3750 | J16: =H16-I16 -> -1598.29 | K16: =E16/B16 -> 0.41935484 | L16: 0.3 | M16: =L16-K16 -> -0.11935484 | N16: =IFERROR(H16/E16,"") -> 165.51615 | O16: 250 | P16: =N16-O16 -> -84.483846 | R16: Nº Leads | S16: =B5 -> 589
A17: 46003 | B17: 21 | C17: 49 | D17: =B17-C17 -> -28 | E17: 5 | F17: 12 | G17: =E17-F17 -> -7 | H17: 955.06 | I17: 3750 | J17: =H17-I17 -> -2794.94 | K17: =E17/B17 -> 0.23809524 | L17: 0.3 | M17: =L17-K17 -> 0.061904762 | N17: =IFERROR(H17/E17,"") -> 191.012 | O17: 250 | P17: =N17-O17 -> -58.988 | R17: Nº Vendas | S17: =E5 -> 165
A18: 46004 | B18: 0 | C18: 49 | D18: =B18-C18 -> -49 | E18: 3 | F18: 0 | G18: =E18-F18 -> 3 | H18: 468.47 | I18: 0 | J18: =H18-I18 -> 468.47 | K18: =E18/B18 -> #DIV/0! | L18: 0.3 | M18: =L18-K18 -> #DIV/0! | N18: =IFERROR(H18/E18,"") -> 156.15667 | O18: 250 | P18: =N18-O18 -> -93.843333 | R18: Taxa Conversão | S18: =E5/B5 -> 0.28013582
A19: 46005 | H19: 0
A20: 46006 | B20: 47 | C20: 49 | D20: =B20-C20 -> -2 | E20: 10 | F20: 12 | G20: =E20-F20 -> -2 | H20: 3826.51 | I20: 3750 | J20: =H20-I20 -> 76.51 | K20: =E20/B20 -> 0.21276596 | L20: 0.3 | M20: =L20-K20 -> 0.087234043 | N20: =IFERROR(H20/E20,"") -> 382.651 | O20: 250 | P20: =N20-O20 -> 132.651
A21: 46007 | B21: 45 | C21: 49 | D21: =B21-C21 -> -4 | E21: 10 | F21: 12 | G21: =E21-F21 -> -2 | H21: 1769.5 | I21: 3750 | J21: =H21-I21 -> -1980.5 | K21: =E21/B21 -> 0.22222222 | L21: 0.3 | M21: =L21-K21 -> 0.077777778 | N21: =IFERROR(H21/E21,"") -> 176.95 | O21: 250 | P21: =N21-O21 -> -73.05
A22: 46008 | B22: 31 | C22: 49 | D22: =B22-C22 -> -18 | E22: 7 | F22: 12 | G22: =E22-F22 -> -5 | H22: 1908.02 | I22: 3750 | J22: =H22-I22 -> -1841.98 | K22: =E22/B22 -> 0.22580645 | L22: 0.3 | M22: =L22-K22 -> 0.074193548 | N22: =IFERROR(H22/E22,"") -> 272.57429 | O22: 250 | P22: =N22-O22 -> 22.574286
A23: 46009 | B23: 15 | C23: 49 | D23: =B23-C23 -> -34 | E23: 6 | F23: 12 | G23: =E23-F23 -> -6 | H23: 3946.56 | I23: 3750 | J23: =H23-I23 -> 196.56 | K23: =E23/B23 -> 0.4 | L23: 0.3 | M23: =L23-K23 -> -0.1 | N23: =IFERROR(H23/E23,"") -> 657.76 | O23: 250 | P23: =N23-O23 -> 407.76
A24: 46010 | B24: 12 | C24: 49 | D24: =B24-C24 -> -37 | E24: 6 | F24: 12 | G24: =E24-F24 -> -6 | H24: 1323.62 | I24: 3750 | J24: =H24-I24 -> -2426.38 | K24: =E24/B24 -> 0.5 | L24: 0.3 | M24: =L24-K24 -> -0.2 | N24: =IFERROR(H24/E24,"") -> 220.60333 | O24: 250 | P24: =N24-O24 -> -29.396667
A25: 46011 | B25: 6 | C25: 49 | D25: =B25-C25 -> -43 | E25: 2 | F25: 0 | G25: =E25-F25 -> 2 | H25: 172.06 | I25: 0 | J25: =H25-I25 -> 172.06 | K25: =E25/B25 -> 0.33333333 | L25: 0.3 | M25: =L25-K25 -> -0.033333333 | N25: =IFERROR(H25/E25,"") -> 86.03 | O25: 250 | P25: =N25-O25 -> -163.97
A26: 46012 | H26: 0
A27: 46013 | B27: 23 | C27: 49 | D27: =B27-C27 -> -26 | E27: 8 | F27: 12 | G27: =E27-F27 -> -4 | H27: 1535.96 | I27: 3750 | J27: =H27-I27 -> -2214.04 | K27: =E27/B27 -> 0.34782609 | L27: 0.3 | M27: =L27-K27 -> -0.047826087 | N27: =IFERROR(H27/E27,"") -> 191.995 | O27: 250 | P27: =N27-O27 -> -58.005
A28: 46014 | B28: 0 | C28: 49 | D28: =B28-C28 -> -49 | E28: 0 | F28: 12 | G28: =E28-F28 -> -12 | H28: 0 | I28: 3750 | J28: =H28-I28 -> -3750 | K28: =E28/B28 -> #DIV/0! | L28: 0.3 | M28: =L28-K28 -> #DIV/0! | N28: =IFERROR(H28/E28,"") | O28: 250 | P28: =N28-O28 -> -250
A29: 46015 | B29: 0 | C29: 0 | D29: 0 | E29: 0 | F29: 0 | G29: =E29-F29 -> 0 | H29: 0 | I29: 0 | J29: =H29-I29 -> 0 | K29: =E29/B29 -> #DIV/0! | L29: 0.3 | M29: =L29-K29 -> #DIV/0! | N29: =IFERROR(H29/E29,"") | O29: 250 | P29: =N29-O29 -> -250
A30: 46016 | B30: 0 | C30: 0 | D30: 0 | E30: 0 | F30: 0 | G30: =E30-F30 -> 0 | H30: 0 | I30: 0 | J30: =H30-I30 -> 0 | K30: =E30/B30 -> #DIV/0! | L30: 0.3 | M30: =L30-K30 -> #DIV/0! | N30: =IFERROR(H30/E30,"") | O30: 250 | P30: =N30-O30 -> -250
A31: 46017 | B31: 0 | C31: 49 | D31: =B31-C31 -> -49 | E31: 0 | F31: 12 | G31: =E31-F31 -> -12 | H31: 0 | I31: 3750 | J31: =H31-I31 -> -3750 | K31: =E31/B31 -> #DIV/0! | L31: 0.3 | M31: =L31-K31 -> #DIV/0! | N31: =IFERROR(H31/E31,"") | O31: 250 | P31: =N31-O31 -> -250
A32: 46018 | B32: 0 | C32: 49 | D32: =B32-C32 -> -49 | E32: 0 | F32: 12 | G32: =E32-F32 -> -12 | H32: 0 | I32: 3750 | J32: =H32-I32 -> -3750 | K32: =E32/B32 -> #DIV/0! | L32: 0.3 | M32: =L32-K32 -> #DIV/0! | N32: =IFERROR(H32/E32,"") | O32: 250 | P32: =N32-O32 -> -250
A33: 46019
A34: 46020 | B34: 0 | C34: 49 | D34: =B34-C34 -> -49 | E34: 0 | F34: 12 | G34: =E34-F34 -> -12 | H34: 0 | I34: 3750 | J34: =H34-I34 -> -3750 | K34: =E34/B34 -> #DIV/0! | L34: 0.3 | M34: =L34-K34 -> #DIV/0! | N34: =IFERROR(H34/E34,"") | O34: 250 | P34: =N34-O34 -> -250
A35: 46021 | B35: 0 | C35: 0 | D35: 0 | E35: 0 | F35: 0 | G35: =E35-F35 -> 0 | H35: 0 | I35: 0 | J35: =H35-I35 -> 0 | K35: =E35/B35 -> #DIV/0! | L35: 0.3 | M35: =L35-K35 -> #DIV/0! | N35: =IFERROR(H35/E35,"") | O35: 250 | P35: =N35-O35 -> -250
A36: 46022 | B36: 0 | C36: 0 | D36: 0 | E36: 0 | F36: 0 | G36: =E36-F36 -> 0 | H36: 0 | I36: 0 | J36: =H36-I36 -> 0 | K36: =E36/B36 -> #DIV/0! | L36: 0.3 | M36: =L36-K36 -> #DIV/0! | N36: =IFERROR(H36/E36,"") | O36: 250 | P36: =N36-O36 -> -250
A37: Mirian | B37: =SUM(B38:B67) -> 255 | C37: =SUM(C38:C67) -> 460 | D37: =SUM(D38:D67) -> -205 | E37: =SUM(E38:E67) -> 205 | F37: =SUM(F38:F67) -> 299 | G37: =SUM(G38:G67) -> -94 | H37: =SUM(H38:H67) -> 47680.71 | I37: =SUM(I38:I67) -> 74750 | J37: =SUM(J38:J67) -> -27069.29 | K37: =E37/B37 -> 0.80392157 | L37: 0.5 | M37: =K37-L37 -> 0.30392157 | N37: =IFERROR(H37/E37,"") -> 232.58883 | O37: =O38 -> 250 | P37: =N37-O37 -> -17.411171
A38: 45992 | B38: 21 | C38: 20 | D38: =B38-C38 -> 1 | E38: 15 | F38: 13 | G38: =E38-F38 -> 2 | H38: 2982.33 | I38: 3250 | J38: =H38-I38 -> -267.67 | K38: =E38/B38 -> 0.71428571 | L38: 0.3 | M38: =L38-K38 -> -0.41428571 | N38: =IFERROR(H38/E38,"") -> 198.822 | O38: 250 | P38: =N38-O38 -> -51.178 | R38: MIRIAN
A39: 45993 | B39: 14 | C39: 20 | D39: =B39-C39 -> -6 | E39: 10 | F39: 13 | G39: =E39-F39 -> -3 | H39: 2280.72 | I39: 3250 | J39: =H39-I39 -> -969.28 | K39: =E39/B39 -> 0.71428571 | L39: 0.3 | M39: =L39-K39 -> -0.41428571 | N39: =IFERROR(H39/E39,"") -> 228.072 | O39: 250 | P39: =N39-O39 -> -21.928 | R39: Outubro
A40: 45994 | B40: 14 | C40: 20 | D40: =B40-C40 -> -6 | E40: 10 | F40: 13 | G40: =E40-F40 -> -3 | H40: 2159.59 | I40: 3250 | J40: =H40-I40 -> -1090.41 | K40: =E40/B40 -> 0.71428571 | L40: 0.3 | M40: =L40-K40 -> -0.41428571 | N40: =IFERROR(H40/E40,"") -> 215.959 | O40: 250 | P40: =N40-O40 -> -34.041 | R40: Meta | S40: 65000 | T40: =S40-S43 -> 17319.29
...

Sheet Recompra - 12
B1: Leads | E1: Nº Vendas | H1: Faturamento | K1: Taxa Conversão | N1: Ticket Médio
B2: Realizado | C2: Meta | D2: Gap | E2: Realizado | F2: Meta | G2: Gap | H2: Realizado | I2: Meta | J2: Gap | K2: Realizado | L2: Meta | M2: Gap | N2: Realizado | O2: Meta | P2: Gap
A4: Novembro | B4: =B5+B37+B69 -> 850 | C4: =C5+C37+C69 -> 2818 | D4: =D5+D37+D69 -> -2328 | E4: =E5+E37+E69 -> 691 | F4: =F5+F37+F69 -> 1538 | G4: =G5+G37+G69 -> -725 | H4: =H5+H37+H69 -> 163911.51 | I4: =I5+I37+I69 -> 285000 | J4: =J5+J37+J69 -> -121088.49 | K4: =E4/B4 -> 0.81294118 | L4: 0.6 | M4: =K4-L4 -> 0.21294118 | N4: =H4/E4 -> 237.20913 | O4: 250 | P4: =N4-O4 -> -12.790868
A5: Hagata | B5: =SUM(B6:B35) -> 332 | C5: 1200 | D5: =SUM(D6:D35) -> -1048 | E5: =SUM(E6:E35) -> 250 | F5: =SUM(F6:F35) -> 480 | G5: =SUM(G6:G35) -> -230 | H5: =SUM(H6:H35) -> 59960.03 | I5: =SUM(I6:I35) -> 100000 | J5: =SUM(J6:J35) -> -40039.97 | K5: =E5/B5 -> 0.75301205 | L5: 0.7 | M5: =L5-K5 -> -0.053012048 | N5: =H5/E5 -> 239.84012 | O5: 250 | P5: =N5-O5 -> -10.15988
A6: 45992 | B6: 41 | C6: 60 | D6: =B6-C6 -> -19 | E6: 22 | F6: 20 | G6: =E6-F6 -> 2 | H6: 6492.88 | I6: 5000 | J6: =H6-I6 -> 1492.88 | K6: =E6/B6 -> 0.53658537 | L6: 0.75 | M6: =L6-K6 -> 0.21341463 | N6: =IFERROR(H6/E6,"") -> 295.13091 | O6: 250 | P6: =N6-O6 -> 45.130909 | R6: HAGATA
A7: 45993 | B7: 29 | C7: 60 | D7: =B7-C7 -> -31 | E7: 27 | F7: 20 | G7: =E7-F7 -> 7 | H7: 6337.03 | I7: 5000 | J7: =H7-I7 -> 1337.03 | K7: =E7/B7 -> 0.93103448 | L7: 0.75 | M7: =L7-K7 -> -0.18103448 | N7: =IFERROR(H7/E7,"") -> 234.70481 | O7: 250 | P7: =N7-O7 -> -15.295185 | R7: DEZEMBRO
A8: 45994 | B8: 44 | C8: 60 | D8: =B8-C8 -> -16 | E8: 23 | F8: 20 | G8: =E8-F8 -> 3 | H8: 4140.15 | I8: 5000 | J8: =H8-I8 -> -859.85 | K8: =E8/B8 -> 0.52272727 | L8: 0.75 | M8: =L8-K8 -> 0.22727273 | N8: =IFERROR(H8/E8,"") -> 180.00652 | O8: 250 | P8: =N8-O8 -> -69.993478 | R8: Meta | S8: 100000 | T8: =S8-S11 -> 40039.97
A9: 45995 | B9: 21 | C9: 60 | D9: =B9-C9 -> -39 | E9: 14 | F9: 20 | G9: =E9-F9 -> -6 | H9: 3318.81 | I9: 5000 | J9: =H9-I9 -> -1681.19 | K9: =E9/B9 -> 0.66666667 | L9: 0.75 | M9: =L9-K9 -> 0.083333333 | N9: =IFERROR(H9/E9,"") -> 237.05786 | O9: 250 | P9: =N9-O9 -> -12.942143 | R9: Meta x Dia | S9: =S8/30 -> 3333.3333
A10: 45996 | B10: 20 | C10: 60 | D10: =B10-C10 -> -40 | E10: 12 | F10: 20 | G10: =E10-F10 -> -8 | H10: 2492.96 | I10: 5000 | J10: =H10-I10 -> -2507.04 | K10: =E10/B10 -> 0.6 | L10: 0.75 | M10: =L10-K10 -> 0.15 | N10: =IFERROR(H10/E10,"") -> 207.74667 | O10: 250 | P10: =N10-O10 -> -42.253333 | R10: Meta x Dia Útil | S10: =S8/20 -> 5000
A11: 45997 | B11: 12 | C11: 60 | D11: =B11-C11 -> -48 | E11: 5 | F11: 20 | G11: =E11-F11 -> -15 | H11: 1028.16 | I11: 0 | J11: =H11-I11 -> 1028.16 | K11: =E11/B11 -> 0.41666667 | L11: 0.75 | M11: =L11-K11 -> 0.33333333 | N11: =IFERROR(H11/E11,"") -> 205.632 | O11: 250 | P11: =N11-O11 -> -44.368 | R11: Realizado | S11: =H5 -> 59960.03
A12: 45998 | R12: % da Meta | S12: =S11/S8 -> 0.5996003
A13: 45999 | B13: 26 | C13: 60 | D13: =B13-C13 -> -34 | E13: 21 | F13: 20 | G13: =E13-F13 -> 1 | H13: 5111.57 | I13: 5000 | J13: =H13-I13 -> 111.57 | K13: =E13/B13 -> 0.80769231 | L13: 0.75 | M13: =L13-K13 -> -0.057692308 | N13: =IFERROR(H13/E13,"") -> 243.4081 | O13: 250 | P13: =N13-O13 -> -6.5919048 | R13: Dias Útil Restante | S13: 4
A14: 46000 | B14: 26 | C14: 60 | D14: =B14-C14 -> -34 | E14: 4 | F14: 20 | G14: =E14-F14 -> -16 | H14: 484.79 | I14: 5000 | J14: =H14-I14 -> -4515.21 | K14: =E14/B14 -> 0.15384615 | L14: 0.75 | M14: =L14-K14 -> 0.59615385 | N14: =IFERROR(H14/E14,"") -> 121.1975 | O14: 250 | P14: =N14-O14 -> -128.8025 | R14: Meta dia Acumulado | S14: =(S8-S11)/S13 -> 10009.993
A15: 46001 | B15: 13 | C15: 60 | D15: =B15-C15 -> -47 | E15: 17 | F15: 20 | G15: =E15-F15 -> -3 | H15: 5571.61 | I15: 5000 | J15: =H15-I15 -> 571.61 | K15: =E15/B15 -> 1.3076923 | L15: 0.75 | M15: =L15-K15 -> -0.55769231 | N15: =IFERROR(H15/E15,"") -> 327.74176 | O15: 250 | P15: =N15-O15 -> 77.741765 | R15: Ticket Médio | S15: =N5 -> 239.84012
A16: 46002 | B16: 18 | C16: 60 | D16: =B16-C16 -> -42 | E16: 15 | F16: 20 | G16: =E16-F16 -> -5 | H16: 3229.49 | I16: 5000 | J16: =H16-I16 -> -1770.51 | K16: =E16/B16 -> 0.83333333 | L16: 0.75 | M16: =L16-K16 -> -0.083333333 | N16: =IFERROR(H16/E16,"") -> 215.29933 | O16: 250 | P16: =N16-O16 -> -34.700667 | R16: Nº Leads | S16: =B5 -> 332
A17: 46003 | B17: 22 | C17: 60 | D17: =B17-C17 -> -38 | E17: 10 | F17: 20 | G17: =E17-F17 -> -10 | H17: 2550.03 | I17: 5000 | J17: =H17-I17 -> -2449.97 | K17: =E17/B17 -> 0.45454545 | L17: 0.75 | M17: =L17-K17 -> 0.29545455 | N17: =IFERROR(H17/E17,"") -> 255.003 | O17: 250 | P17: =N17-O17 -> 5.003 | R17: Nº Vendas | S17: =E5 -> 250
A18: 46004 | B18: 0 | C18: 60 | D18: =B18-C18 -> -60 | E18: 8 | F18: 20 | G18: =E18-F18 -> -12 | H18: 2299.85 | I18: 0 | J18: =H18-I18 -> 2299.85 | K18: =E18/B18 -> #DIV/0! | L18: 0.75 | M18: =L18-K18 -> #DIV/0! | N18: =IFERROR(H18/E18,"") -> 287.48125 | O18: 250 | P18: =N18-O18 -> 37.48125 | R18: Taxa Conversão | S18: =E5/B5 -> 0.75301205
A19: 46005
A20: 46006 | B20: 16 | C20: 60 | D20: =B20-C20 -> -44 | E20: 18 | F20: 20 | G20: =E20-F20 -> -2 | H20: 4536.42 | I20: 5000 | J20: =H20-I20 -> -463.58 | K20: =E20/B20 -> 1.125 | L20: 0.75 | M20: =L20-K20 -> -0.375 | N20: =IFERROR(H20/E20,"") -> 252.02333 | O20: 250 | P20: =N20-O20 -> 2.0233333
A21: 46007 | B21: 6 | C21: 60 | D21: =B21-C21 -> -54 | E21: 11 | F21: 20 | G21: =E21-F21 -> -9 | H21: 3583.95 | I21: 5000 | J21: =H21-I21 -> -1416.05 | K21: =E21/B21 -> 1.8333333 | L21: 0.75 | M21: =L21-K21 -> -1.0833333 | N21: =IFERROR(H21/E21,"") -> 325.81364 | O21: 250 | P21: =N21-O21 -> 75.813636
A22: 46008 | B22: 2 | C22: 60 | D22: =B22-C22 -> -58 | E22: 7 | F22: 20 | G22: =E22-F22 -> -13 | H22: 1762.73 | I22: 5000 | J22: =H22-I22 -> -3237.27 | K22: =E22/B22 -> 3.5 | L22: 0.75 | M22: =L22-K22 -> -2.75 | N22: =IFERROR(H22/E22,"") -> 251.81857 | O22: 250 | P22: =N22-O22 -> 1.8185714
A23: 46009 | B23: 4 | C23: 60 | D23: =B23-C23 -> -56 | E23: 10 | F23: 20 | G23: =E23-F23 -> -10 | H23: 2505.84 | I23: 5000 | J23: =H23-I23 -> -2494.16 | K23: =E23/B23 -> 2.5 | L23: 0.75 | M23: =L23-K23 -> -1.75 | N23: =IFERROR(H23/E23,"") -> 250.584 | O23: 250 | P23: =N23-O23 -> 0.584
A24: 46010 | B24: 8 | C24: 60 | D24: =B24-C24 -> -52 | E24: 10 | F24: 20 | G24: =E24-F24 -> -10 | H24: 1532.06 | I24: 5000 | J24: =H24-I24 -> -3467.94 | K24: =E24/B24 -> 1.25 | L24: 0.75 | M24: =L24-K24 -> -0.5 | N24: =IFERROR(H24/E24,"") -> 153.206 | O24: 250 | P24: =N24-O24 -> -96.794
A25: 46011 | B25: 13 | C25: 60 | D25: =B25-C25 -> -47 | E25: 4 | F25: 20 | G25: =E25-F25 -> -16 | H25: 677.6 | I25: 0 | J25: =H25-I25 -> 677.6 | K25: =E25/B25 -> 0.30769231 | L25: 0.75 | M25: =L25-K25 -> 0.44230769 | N25: =IFERROR(H25/E25,"") -> 169.4 | O25: 250 | P25: =N25-O25 -> -80.6
A26: 46012
A27: 46013 | B27: 11 | C27: 60 | D27: =B27-C27 -> -49 | E27: 12 | F27: 20 | G27: =E27-F27 -> -8 | H27: 2304.1 | I27: 5000 | J27: =H27-I27 -> -2695.9 | K27: =E27/B27 -> 1.0909091 | L27: 0.75 | M27: =L27-K27 -> -0.34090909 | N27: =IFERROR(H27/E27,"") -> 192.00833 | O27: 250 | P27: =N27-O27 -> -57.991667
A28: 46014 | B28: 0 | C28: 60 | D28: =B28-C28 -> -60 | E28: 0 | F28: 20 | G28: =E28-F28 -> -20 | H28: 0 | I28: 5000 | J28: =H28-I28 -> -5000 | K28: =E28/B28 -> #DIV/0! | L28: 0.75 | M28: =L28-K28 -> #DIV/0! | N28: =IFERROR(H28/E28,"") | O28: 250 | P28: =N28-O28 -> -250
A29: 46015 | B29: 0 | C29: 0 | D29: =B29-C29 -> 0 | E29: 0 | F29: 0 | G29: =E29-F29 -> 0 | H29: 0 | I29: 0 | J29: =H29-I29 -> 0 | K29: =E29/B29 -> #DIV/0! | L29: 0.75 | M29: =L29-K29 -> #DIV/0! | N29: =IFERROR(H29/E29,"") | O29: 250 | P29: =N29-O29 -> -250
A30: 46016 | B30: 0 | C30: 0 | D30: =B30-C30 -> 0 | E30: 0 | F30: 0 | G30: =E30-F30 -> 0 | H30: 0 | I30: 0 | J30: =H30-I30 -> 0 | K30: =E30/B30 -> #DIV/0! | M30: =L30-K30 -> #DIV/0! | N30: =IFERROR(H30/E30,"") | O30: 250 | P30: =N30-O30 -> -250
A31: 46017 | B31: 0 | C31: 60 | D31: =B31-C31 -> -60 | E31: 0 | F31: 20 | G31: =E31-F31 -> -20 | H31: 0 | I31: 5000 | J31: =H31-I31 -> -5000 | K31: =E31/B31 -> #DIV/0! | L31: 0.75 | M31: =L31-K31 -> #DIV/0! | N31: =IFERROR(H31/E31,"") | O31: 250 | P31: =N31-O31 -> -250
A32: 46018 | B32: 0 | C32: 60 | D32: =B32-C32 -> -60 | E32: 0 | F32: 20 | G32: =E32-F32 -> -20 | H32: 0 | I32: 5000 | J32: =H32-I32 -> -5000 | K32: =E32/B32 -> #DIV/0! | L32: 0.75 | M32: =L32-K32 -> #DIV/0! | N32: =IFERROR(H32/E32,"") | O32: 250 | P32: =N32-O32 -> -250
A33: 46019
A34: 46020 | B34: 0 | C34: 60 | D34: =B34-C34 -> -60 | E34: 0 | F34: 20 | G34: =E34-F34 -> -20 | H34: 0 | I34: 5000 | J34: =H34-I34 -> -5000 | K34: =E34/B34 -> #DIV/0! | L34: 0.75 | M34: =L34-K34 -> #DIV/0! | N34: =IFERROR(H34/E34,"") | O34: 250 | P34: =N34-O34 -> -250
A35: 46021 | B35: 0 | C35: 0 | D35: =B35-C35 -> 0 | E35: 0 | F35: 20 | G35: =E35-F35 -> -20 | H35: 0 | I35: 0 | J35: =H35-I35 -> 0 | K35: =E35/B35 -> #DIV/0! | L35: 0.75 | M35: =L35-K35 -> #DIV/0! | N35: =IFERROR(H35/E35,"") | O35: 250 | P35: =N35-O35 -> -250
A36: 46022 | B36: 0 | C36: 0 | D36: =B36-C36 -> 0 | E36: 0 | F36: 0 | G36: =E36-F36 -> 0 | H36: 0 | I36: 0 | J36: =H36-I36 -> 0 | K36: =E36/B36 -> #DIV/0! | M36: =L36-K36 -> #DIV/0! | N36: =IFERROR(H36/E36,"") | O36: 250 | P36: =N36-O36 -> -250
A37: Gustavo | B37: =SUM(B38:B67) -> 424 | C37: 1200 | D37: =SUM(D38:D67) -> -956 | E37: =SUM(E38:E67) -> 356 | F37: =SUM(F38:F67) -> 851 | G37: =SUM(G38:G67) -> -495 | H37: =SUM(H38:H67) -> 91532.7 | I37: =SUM(I38:I67) -> 135000 | J37: =SUM(J38:J67) -> -43467.3 | K37: =E37/B37 -> 0.83962264 | L37: 0.7 | M37: =L37-K37 -> -0.13962264 | N37: =H37/E37 -> 257.11433 | O37: 250 | P37: =N37-O37 -> 7.1143258
A38: 45992 | B38: 27 | C38: 60 | D38: =B38-C38 -> -33 | E38: 17 | F38: 27 | G38: =E38-F38 -> -10 | H38: 4968.35 | I38: 6750 | J38: =H38-I38 -> -1781.65 | K38: =E38/B38 -> 0.62962963 | L38: 0.7 | M38: =L38-K38 -> 0.07037037 | N38: =IFERROR(H38/E38,"") -> 292.25588 | O38: 250 | P38: =N38-O38 -> 42.255882 | R38: GUSTAVO
A39: 45993 | B39: 26 | C39: 60 | D39: =B39-C39 -> -34 | E39: 19 | F39: 27 | G39: =E39-F39 -> -8 | H39: 8389.85 | I39: 6750 | J39: =H39-I39 -> 1639.85 | K39: =E39/B39 -> 0.73076923 | L39: 0.7 | M39: =L39-K39 -> -0.030769231 | N39: =IFERROR(H39/E39,"") -> 441.57105 | O39: 250 | P39: =N39-O39 -> 191.57105 | R39: Outubro
A40: 45994 | B40: 12 | C40: 60 | D40: =B40-C40 -> -48 | E40: 14 | F40: 27 | G40: =E40-F40 -> -13 | H40: 3934.29 | I40: 6750 | J40: =H40-I40 -> -2815.71 | K40: =E40/B40 -> 1.1666667 | L40: 0.7 | M40: =L40-K40 -> -0.46666667 | N40: =IFERROR(H40/E40,"") -> 281.02071 | O40: 250 | P40: =N40-O40 -> 31.020714 | R40: Meta | S40: 135000 | T40: =S40-S43 -> 43467.3
A41: 45995 | B41: 23 | C41: 60 | D41: =B41-C41 -> -37 | E41: 22 | F41: 27 | G41: =E41-F41 -> -5 | H41: 4045.78 | I41: 6750 | J41: =H41-I41 -> -2704.22 | K41: =E41/B41 -> 0.95652174 | L41: 0.7 | M41: =L41-K41 -> -0.25652174 | N41: =IFERROR(H41/E41,"") -> 183.89909 | O41: 250 | P41: =N41-O41 -> -66.100909 | R41: Meta x Dia | S41: =S40/30 -> 4500
...

Sheet RONDAS
A1: Ronda | B1: 10h | E1: 12h | H1: 14h | K1: 16h | N1: 18h | Q1: 20h
A2: Dia | B2: Meta | C2: Realizado | D2: Gap | E2: Meta | F2: Realizado | G2: Gap | H2: Meta | I2: Realizado | J2: Gap | K2: Meta | L2: Realizado | M2: Gap | N2: Meta | O2: Realizado | P2: Gap | Q2: Meta | R2: Realizado | S2: Gap
C3: R$ 0,00
A4: 45993 | B4: =SUM(B5:B12) -> 5189.73 | C4: =SUM(C5:C11) -> 1956.99 | D4: =C4-B4 -> -3232.74 | E4: =B4*2 -> 10379.46 | F4: =SUM(F5:F11) -> 5702.36 | G4: =F4-E4 -> -4677.1 | H4: =B4*3 -> 15569.19 | I4: =SUM(I5:I11) -> 7235.59 | J4: =I4-H4 -> -8333.6 | K4: =B4*4 -> 20758.92 | L4: =SUM(L5:L11) -> 8658.51 | M4: =L4-K4 -> -12100.41 | N4: =B4*5 -> 25948.65 | O4: =SUM(O5:O11) -> 12984.5 | P4: =O4-N4 -> -12964.15 | Q4: =N4 -> 25948.65 | R4: =SUM(R5:R11) -> 0 | S4: =Q4-R4 -> 25948.65
A5: HAGATA | B5: 917.58 | C5: 0 | D5: =C5-B5 -> -917.58 | E5: =B5*2 -> 1835.16 | F5: 1454.09 | G5: =F5-E5 -> -381.07 | H5: =B5*3 -> 2752.74 | I5: 1604.32 | J5: =H5-I5 -> 1148.42 | K5: =B5*4 -> 3670.32 | L5: 1604.32 | M5: =L5-K5 -> -2066 | N5: =B5*5 -> 4587.9 | O5: 4140.15 | P5: =O5-N5 -> -447.75 | Q5: =N5 -> 4587.9 | R5: 0 | S5: =Q5-R5 -> 4587.9
A6: GUSTAVO | B6: 1351.58 | C6: 1250 | D6: =C6-B6 -> -101.58 | E6: =B6*2 -> 2703.16 | F6: 2045.48 | G6: =F6-E6 -> -657.68 | H6: =B6*3 -> 4054.74 | I6: 3078.48 | J6: =H6-I6 -> 976.26 | K6: =B6*4 -> 5406.32 | L6: 3236.4 | M6: =L6-K6 -> -2169.92 | N6: =B6*5 -> 6757.9 | O6: 3934.29 | P6: =O6-N6 -> -2823.61 | Q6: =N6 -> 6757.9 | R6: 0 | S6: =Q6-R6 -> 6757.9
A7: THALIA | B7: 757.07 | C7: 281.99 | D7: =C7-B7 -> -475.08 | E7: =B7*2 -> 1514.14 | F7: 416.99 | G7: =F7-E7 -> -1097.15 | H7: =B7*3 -> 2271.21 | I7: 416.99 | J7: =H7-I7 -> 1854.22 | K7: =B7*4 -> 3028.28 | L7: 1291.99 | M7: =L7-K7 -> -1736.29 | N7: =B7*5 -> 3785.35 | O7: 2051.6 | P7: =O7-N7 -> -1733.75 | Q7: =N7 -> 3785.35 | R7: 0 | S7: =Q7-R7 -> 3785.35
A8: ISA C | B8: 551.89 | C8: 0 | D8: =C8-B8 -> -551.89 | E8: =B8*2 -> 1103.78 | F8: 0 | G8: =F8-E8 -> -1103.78 | H8: =B8*3 -> 1655.67 | I8: 0 | J8: =H8-I8 -> 1655.67 | K8: =B8*4 -> 2207.56 | L8: 0 | M8: =L8-K8 -> -2207.56 | N8: =B8*5 -> 2759.45 | O8: 0 | P8: =O8-N8 -> -2759.45 | Q8: =N8 -> 2759.45 | R8: 0 | S8: =Q8-R8 -> 2759.45
A9: MIRIAN | B9: 633.74 | C9: 425 | D9: =C9-B9 -> -208.74 | E9: =B9*2 -> 1267.48 | F9: 1680.86 | G9: =F9-E9 -> 413.38 | H9: =B9*3 -> 1901.22 | I9: 2030.86 | J9: =H9-I9 -> -129.64 | K9: =B9*4 -> 2534.96 | L9: 2030.86 | M9: =L9-K9 -> -504.1 | N9: =B9*5 -> 3168.7 | O9: 2159.59 | P9: =O9-N9 -> -1009.11 | Q9: =N9 -> 3168.7 | R9: 0 | S9: =Q9-R9 -> 3168.7
A10: GABRIELA | B10: 489.28 | C10: 0 | D10: =C10-B10 -> -489.28 | E10: =B10*2 -> 978.56 | F10: 49.94 | G10: =F10-E10 -> -928.62 | H10: =B10*3 -> 1467.84 | I10: 49.94 | J10: =H10-I10 -> 1417.9 | K10: =B10*4 -> 1957.12 | L10: 439.94 | M10: =L10-K10 -> -1517.18 | N10: =B10*5 -> 2446.4 | O10: 439.94 | P10: =O10-N10 -> -2006.46 | Q10: =N10 -> 2446.4 | R10: 0 | S10: =Q10-R10 -> 2446.4
A11: ISABELA H | B11: 488.59 | C11: 0 | D11: =C11-B11 -> -488.59 | E11: =B11*2 -> 977.18 | F11: 55 | G11: =F11-E11 -> -922.18 | H11: =B11*3 -> 1465.77 | I11: 55 | J11: =H11-I11 -> 1410.77 | K11: =B11*4 -> 1954.36 | L11: 55 | M11: =L11-K11 -> -1899.36 | N11: =B11*5 -> 2442.95 | O11: 258.93 | P11: =O11-N11 -> -2184.02 | Q11: =N11 -> 2442.95 | R11: 0 | S11: =Q11-R11 -> 2442.95
C12: R$ 0,00
A13: 45995 | B13: =SUM(B14:B21) -> 5404.92 | C13: =SUM(C14:C20) -> 3370.36 | D13: =C13-B13 -> -2034.56 | E13: =B13*2 -> 10809.84 | F13: =SUM(F14:F20) -> 5646.3 | G13: =F13-E13 -> -5163.54 | H13: =B13*3 -> 16214.76 | I13: =SUM(I14:I20) -> 6589.47 | J13: =I13-H13 -> -9625.29 | K13: =B13*4 -> 21619.68 | L13: =SUM(L14:L20) -> 9253.25 | M13: =L13-K13 -> -12366.43 | N13: =B13*5 -> 27024.6 | O13: =SUM(O14:O20) -> 11177.09 | P13: =O13-N13 -> -15847.51 | Q13: =N13 -> 27024.6 | R13: =SUM(R14:R214) -> 377917.16 | S13: =R13-Q13 -> 350892.56
A14: HAGATA | B14: 976.82 | C14: 990.09 | D14: =C14-B14 -> 13.27 | E14: =B14*2 -> 1953.64 | F14: 1251.17 | G14: =F14-E14 -> -702.47 | H14: =B14*3 -> 2930.46 | I14: 1701.17 | J14: =I14-H14 -> -1229.29 | K14: =B14*4 -> 3907.28 | L14: 1889.96 | M14: =L14-K14 -> -2017.32 | N14: =B14*5 -> 4884.1 | O14: 3100.81 | P14: =O14-N14 -> -1783.29 | Q14: =N14 -> 4884.1 | R14: 3316.81 | S14: =R14-Q14 -> -1567.29
A15: GUSTAVO | B15: 1384.79 | C15: 1559.06 | D15: =C15-B15 -> 174.27 | E15: =B15*2 -> 2769.58 | F15: 2153.06 | G15: =F15-E15 -> -616.52 | H15: =B15*3 -> 4154.37 | I15: 2398.64 | J15: =I15-H15 -> -1755.73 | K15: =B15*4 -> 5539.16 | L15: 3280.64 | M15: =L15-K15 -> -2258.52 | N15: =B15*5 -> 6923.95 | O15: 3478.13 | P15: =O15-N15 -> -3445.82 | Q15: =N15 -> 6923.95 | R15: 4424.29 | S15: =R15-Q15 -> -2499.66
A16: THALIA | B16: 777.47 | C16: 353 | D16: =C16-B16 -> -424.47 | E16: =B16*2 -> 1554.94 | F16: 786.52 | G16: =F16-E16 -> -768.42 | H16: =B16*3 -> 2332.41 | I16: 993.27 | J16: =I16-H16 -> -1339.14 | K16: =B16*4 -> 3109.88 | L16: 1671.24 | M16: =L16-K16 -> -1438.64 | N16: =B16*5 -> 3887.35 | O16: 1786.74 | P16: =O16-N16 -> -2100.61 | Q16: =N16 -> 3887.35 | R16: 1786.24 | S16: =R16-Q16 -> -2101.11
A17: ISA C | B17: 582.77 | C17: 0 | D17: =C17-B17 -> -582.77 | E17: =B17*2 -> 1165.54 | F17: 134.39 | G17: =F17-E17 -> -1031.15 | H17: =B17*3 -> 1748.31 | I17: 75.31 | J17: =I17-H17 -> -1673 | K17: =B17*4 -> 2331.08 | L17: 591.26 | M17: =L17-K17 -> -1739.82 | N17: =B17*5 -> 2913.85 | O17: 591.26 | P17: =O17-N17 -> -2322.59 | Q17: =N17 -> 2913.85 | R17: 713.56 | S17: =R17-Q17 -> -2200.29
A18: MIRIAN | B18: 677.38 | C18: 468.21 | D18: =C18-B18 -> -209.17 | E18: =B18*2 -> 1354.76 | F18: 1009.2 | G18: =F18-E18 -> -345.56 | H18: =B18*3 -> 2032.14 | I18: 1009.2 | J18: =I18-H18 -> -1022.94 | K18: =B18*4 -> 2709.52 | L18: 1009.2 | M18: =L18-K18 -> -1700.32 | N18: =B18*5 -> 3386.9 | O18: 1409.2 | P18: =O18-N18 -> -1977.7 | Q18: =N18 -> 3386.9 | R18: 1409.2 | S18: =R18-Q18 -> -1977.7
A19: GABRIELA | B19: 512.89 | C19: 0 | D19: =C19-B19 -> -512.89 | E19: =B19*2 -> 1025.78 | F19: 0 | G19: =F19-E19 -> -1025.78 | H19: =B19*3 -> 1538.67 | I19: 99.92 | J19: =I19-H19 -> -1438.75 | K19: =B19*4 -> 2051.56 | L19: 498.99 | M19: =L19-K19 -> -1552.57 | N19: =B19*5 -> 2564.45 | O19: 498.99 | P19: =O19-N19 -> -2065.46 | Q19: =N19 -> 2564.45 | R19: 498.99 | S19: =R19-Q19 -> -2065.46
A20: ISABELA H | B20: 492.8 | C20: 0 | D20: =C20-B20 -> -492.8 | E20: =B20*2 -> 985.6 | F20: 311.96 | G20: =F20-E20 -> -673.64 | H20: =B20*3 -> 1478.4 | I20: 311.96 | J20: =I20-H20 -> -1166.44 | K20: =B20*4 -> 1971.2 | L20: 311.96 | M20: =L20-K20 -> -1659.24 | N20: =B20*5 -> 2464 | O20: 311.96 | P20: =O20-N20 -> -2152.04 | Q20: =N20 -> 2464 | R20: 311.96 | S20: =R20-Q20 -> -2152.04
C21: R$ 0,00 | R21: 677.36
A22: 45996 | B22: =SUM(B23:B30) -> 5591.67 | C22: =SUM(C23:C29) -> 4164.1 | D22: =C22-B22 -> -1427.57 | E22: =B22*2 -> 11183.34 | F22: =SUM(F23:F29) -> 5992.07 | G22: =F22-E22 -> -5191.27 | H22: =B22*3 -> 16775.01 | I22: =SUM(I23:I29) -> 9476.2 | J22: =I22-H22 -> -7298.81 | K22: =B22*4 -> 22366.68 | L22: =SUM(L23:L29) -> 11593.59 | M22: =L22-K22 -> -10773.09 | N22: =B22*5 -> 27958.35 | O22: =SUM(O23:O29) -> 14482.87 | P22: =O22-N22 -> -13475.48 | Q22: =N22 -> 27958.35 | R22: 18642.39 | S22: =R22-Q22 -> -9315.96
A23: HAGATA | B23: 996.36 | C23: 0 | D23: =C23-B23 -> -996.36 | E23: =B23*2 -> 1992.72 | F23: 1074.75 | G23: =F23-E23 -> -917.97 | H23: =B23*3 -> 2989.08 | I23: 1384.75 | J23: =I23-H23 -> -1604.33 | K23: =B23*4 -> 3985.44 | L23: 1574.94 | M23: =L23-K23 -> -2410.5 | N23: =B23*5 -> 4981.8 | O23: 1574.94 | P23: =O23-N23 -> -3406.86 | Q23: =N23 -> 4981.8 | R23: 0 | S23: =R23-Q23 -> -4981.8
A24: GUSTAVO | B24: 1420.77 | C24: 1247.75 | D24: =C24-B24 -> -173.02 | E24: =B24*2 -> 2841.54 | F24: 1247.75 | G24: =F24-E24 -> -1593.79 | H24: =B24*3 -> 4262.31 | I24: 2559.59 | J24: =I24-H24 -> -1702.72 | K24: =B24*4 -> 5683.08 | L24: 3894.56 | M24: =L24-K24 -> -1788.52 | N24: =B24*5 -> 7103.85 | O24: 5710.81 | P24: =O24-N24 -> -1393.04 | Q24: =N24 -> 7103.85 | R24: 0 | S24: =R24-Q24 -> -7103.85
A25: THALIA | B25: 803.73 | C25: 618 | D25: =C25-B25 -> -185.73 | E25: =B25*2 -> 1607.46 | F25: 720.59 | G25: =F25-E25 -> -886.87 | H25: =B25*3 -> 2411.19 | I25: 1574.71 | J25: =I25-H25 -> -836.48 | K25: =B25*4 -> 3214.92 | L25: 1804.57 | M25: =L25-K25 -> -1410.35 | N25: =B25*5 -> 4018.65 | O25: 2486.57 | P25: =O25-N25 -> -1532.08 | Q25: =N25 -> 4018.65 | R25: 0 | S25: =R25-Q25 -> -4018.65
A26: ISA C | B26: 610.28 | C26: 548.01 | D26: =C26-B26 -> -62.27 | E26: =B26*2 -> 1220.56 | F26: 606.07 | G26: =F26-E26 -> -614.49 | H26: =B26*3 -> 1830.84 | I26: 606.07 | J26: =I26-H26 -> -1224.77 | K26: =B26*4 -> 2441.12 | L26: 719.34 | M26: =L26-K26 -> -1721.78 | N26: =B26*5 -> 3051.4 | O26: 816.61 | P26: =O26-N26 -> -2234.79 | Q26: =N26 -> 3051.4 | R26: 0 | S26: =R26-Q26 -> -3051.4
A27: MIRIAN | B27: 702.1 | C27: 698 | D27: =C27-B27 -> -4.1 | E27: =B27*2 -> 1404.2 | F27: 1019.19 | G27: =F27-E27 -> -385.01 | H27: =B27*3 -> 2106.3 | I27: 1694.19 | J27: =I27-H27 -> -412.11 | K27: =B27*4 -> 2808.4 | L27: 1802.35 | M27: =L27-K27 -> -1006.05 | N27: =B27*5 -> 3510.5 | O27: 1802.35 | P27: =O27-N27 -> -1708.15 | Q27: =N27 -> 3510.5 | R27: 0 | S27: =R27-Q27 -> -3510.5
A28: GABRIELA | B28: 538.73 | C28: 424.86 | D28: =C28-B28 -> -113.87 | E28: =B28*2 -> 1077.46 | F28: 696.24 | G28: =F28-E28 -> -381.22 | H28: =B28*3 -> 1616.19 | I28: 1029.41 | J28: =I28-H28 -> -586.78 | K28: =B28*4 -> 2154.92 | L28: 1170.35 | M28: =L28-K28 -> -984.57 | N28: =B28*5 -> 2693.65 | O28: 1464.11 | P28: =O28-N28 -> -1229.54 | Q28: =N28 -> 2693.65 | R28: 0 | S28: =R28-Q28 -> -2693.65
A29: ISABELA H | B29: 519.7 | C29: 627.48 | D29: =C29-B29 -> 107.78 | E29: =B29*2 -> 1039.4 | F29: 627.48 | G29: =F29-E29 -> -411.92 | H29: =B29*3 -> 1559.1 | I29: 627.48 | J29: =I29-H29 -> -931.62 | K29: =B29*4 -> 2078.8 | L29: 627.48 | M29: =L29-K29 -> -1451.32 | N29: =B29*5 -> 2598.5 | O29: 627.48 | P29: =O29-N29 -> -1971.02 | Q29: =N29 -> 2598.5 | R29: 0 | S29: =R29-Q29 -> -2598.5
C30: R$ 0,00 | R30: 677.36
A31: 45997 | B31: =SUM(B32:B39) -> 3700 | C31: =SUM(C32:C38) -> 1567.45 | D31: =C31-B31 -> -2132.55 | E31: =B31*2 -> 7400 | F31: =SUM(F32:F38) -> 3570.62 | G31: =F31-E31 -> -3829.38 | H31: =B31*3 -> 11100 | I31: =SUM(I32:I38) -> 0 | J31: =I31-H31 -> -11100 | K31: =B31*4 -> 14800 | L31: =SUM(L32:L38) -> 0 | M31: =L31-K31 -> -14800 | N31: =B31*5 -> 18500 | O31: =SUM(O32:O38) -> 0 | P31: =O31-N31 -> -18500 | Q31: =N31 -> 18500 | R31: 18642.39 | S31: =R31-Q31 -> 142.39
A32: HAGATA | B32: 800 | C32: 0 | D32: =C32-B32 -> -800 | E32: =B32*2 -> 1600 | F32: 217.31 | G32: =F32-E32 -> -1382.69 | H32: =B32*3 -> 2400 | I32: 0 | J32: =I32-H32 -> -2400 | K32: =B32*4 -> 3200 | L32: 0 | M32: =L32-K32 -> -3200 | N32: =B32*5 -> 4000 | O32: 0 | P32: =O32-N32 -> -4000 | Q32: =N32 -> 4000 | R32: 0 | S32: =R32-Q32 -> -4000
A33: GUSTAVO | B33: 1000 | C33: 1143.96 | D33: =C33-B33 -> 143.96 | E33: =B33*2 -> 2000 | F33: 2104.8 | G33: =F33-E33 -> 104.8 | H33: =B33*3 -> 3000 | I33: 0 | J33: =I33-H33 -> -3000 | K33: =B33*4 -> 4000 | L33: 0 | M33: =L33-K33 -> -4000 | N33: =B33*5 -> 5000 | O33: 0 | P33: =O33-N33 -> -5000 | Q33: =N33 -> 5000 | R33: 0 | S33: =R33-Q33 -> -5000
A34: THALIA | B34: 800 | C34: 423.49 | D34: =C34-B34 -> -376.51 | E34: =B34*2 -> 1600 | F34: 611.96 | G34: =F34-E34 -> -988.04 | H34: =B34*3 -> 2400 | I34: 0 | J34: =I34-H34 -> -2400 | K34: =B34*4 -> 3200 | L34: 0 | M34: =L34-K34 -> -3200 | N34: =B34*5 -> 4000 | O34: 0 | P34: =O34-N34 -> -4000 | Q34: =N34 -> 4000 | R34: 0 | S34: =R34-Q34 -> -4000
A35: ISA C | B35: 600 | C35: 0 | D35: =C35-B35 -> -600 | E35: =B35*2 -> 1200 | F35: 636.55 | G35: =F35-E35 -> -563.45 | H35: =B35*3 -> 1800 | I35: 0 | J35: =I35-H35 -> -1800 | K35: =B35*4 -> 2400 | L35: 0 | M35: =L35-K35 -> -2400 | N35: =B35*5 -> 3000 | O35: 0 | P35: =O35-N35 -> -3000 | Q35: =N35 -> 3000 | R35: 0 | S35: =R35-Q35 -> -3000
A36: MIRIAN | B36: 500 | C36: 0 | D36: =C36-B36 -> -500 | E36: =B36*2 -> 1000 | F36: 0 | G36: =F36-E36 -> -1000 | H36: =B36*3 -> 1500 | I36: 0 | J36: =I36-H36 -> -1500 | K36: =B36*4 -> 2000 | L36: 0 | M36: =L36-K36 -> -2000 | N36: =B36*5 -> 2500 | O36: 0 | P36: =O36-N36 -> -2500 | Q36: =N36 -> 2500 | R36: 0 | S36: =R36-Q36 -> -2500
A37: GABRIELA | B37: 0 | C37: 0 | D37: =C37-B37 -> 0 | E37: =B37*2 -> 0 | F37: 0 | G37: =F37-E37 -> 0 | H37: =B37*3 -> 0 | I37: 0 | J37: =I37-H37 -> 0 | K37: =B37*4 -> 0 | L37: 0 | M37: =L37-K37 -> 0 | N37: =B37*5 -> 0 | O37: 0 | P37: =O37-N37 -> 0 | Q37: =N37 -> 0 | R37: 0 | S37: =R37-Q37 -> 0
A38: ISABELA H | B38: 0 | C38: 0 | D38: =C38-B38 -> 0 | E38: =B38*2 -> 0 | F38: 0 | G38: =F38-E38 -> 0 | H38: =B38*3 -> 0 | I38: 0 | J38: =I38-H38 -> 0 | K38: =B38*4 -> 0 | L38: 0 | M38: =L38-K38 -> 0 | N38: =B38*5 -> 0 | O38: 0 | P38: =O38-N38 -> 0 | Q38: =N38 -> 0 | R38: 0 | S38: =R38-Q38 -> 0
C39: R$ 0,00 | R39: 677.36
A40: 45999 | B40: =SUM(B41:B48) -> 5134.7 | C40: =SUM(C41:C47) -> 1392.39 | D40: =C40-B40 -> -3742.31 | E40: =B40*2 -> 10269.4 | F40: =SUM(F41:F47) -> 2499.69 | G40: =F40-E40 -> -7769.71 | H40: =B40*3 -> 15404.1 | I40: =SUM(I41:I47) -> 4836.39 | J40: =I40-H40 -> -10567.71 | K40: =B40*4 -> 20538.8 | L40: =SUM(L41:L47) -> 8629.34 | M40: =L40-K40 -> -11909.46 | N40: =B40*5 -> 25673.5 | O40: =SUM(O41:O47) -> 13970.3 | P40: =O40-N40 -> -11703.2 | Q40: =N40 -> 25673.5 | R40: 18033.93 | S40: =R40-Q40 -> -7639.57
...

Sheet Página6
A1: 80% da meta
A2: Vendedor | B2: Meta | C2: Realizado | D2: 80% da meta | E2: Falta p/ 80% | F2: Precisa/dia (4 dias)
A3: Hagata | B3: R$ 100.000,00 | C3: R$ 59.960,03 | D3: R$ 80.000,00 | E3: R$ 20.039,97 | F3: R$ 5.010,00/dia
A4: Gustavo | B4: R$ 135.000,00 | C4: R$ 91.532,70 | D4: R$ 108.000,00 | E4: R$ 16.467,30 | F4: R$ 4.116,83/dia
A5: Thalia | B5: R$ 75.000,00 | C5: R$ 39.760,68 | D5: R$ 60.000,00 | E5: R$ 20.239,32 | F5: R$ 5.059,83/dia
A6: Mirian | B6: R$ 65.000,00 | C6: R$ 47.680,71 | D6: R$ 52.000,00 | E6: R$ 4.319,29 | F6: R$ 1.079,83/dia
A7: Gabriela | B7: R$ 45.000,00 | C7: R$ 13.834,16 | D7: R$ 36.000,00 | E7: R$ 22.165,84 | F7: R$ 5.541,46/dia
A8: Isabella | B8: R$ 50.000,00 | C8: R$ 12.418,78 | D8: R$ 40.000,00 | E8: R$ 27.581,22 | F8: R$ 6.895,31/dia | I8: 80% da meta
I9: Vendedor | J9: Meta | K9: Realizado | L9: 80% da meta | M9: Falta p/ 80% | N9: Precisa/dia (4 dias)
I10: Hagata | J10: R$ 100.000,00 | K10: R$ 59.960,03 | L10: R$ 80.000,00 | M10: R$ 20.039,97 | N10: R$ 5.010,00/dia
A11: 90% da meta | I11: 90% da meta
A12: Vendedor | B12: Meta | C12: Realizado | D12: 90% da meta | E12: Falta p/ 90% | F12: Precisa/dia (4 dias) | I12: Vendedor | J12: Meta | K12: Realizado | L12: 90% da meta | M12: Falta p/ 90% | N12: Precisa/dia (4 dias)
A13: Hagata | B13: R$ 100.000,00 | C13: R$ 59.960,03 | D13: R$ 90.000,00 | E13: R$ 30.039,97 | F13: R$ 7.510,00/dia | I13: Hagata | J13: R$ 100.000,00 | K13: R$ 59.960,03 | L13: R$ 90.000,00 | M13: R$ 30.039,97 | N13: R$ 7.510,00/dia
A14: Gustavo | B14: R$ 135.000,00 | C14: R$ 91.532,70 | D14: R$ 121.500,00 | E14: R$ 29.967,30 | F14: R$ 7.491,83/dia
A15: Thalia | B15: R$ 75.000,00 | C15: R$ 39.760,68 | D15: R$ 67.500,00 | E15: R$ 27.739,32 | F15: R$ 6.934,83/dia
A16: Mirian | B16: R$ 65.000,00 | C16: R$ 47.680,71 | D16: R$ 58.500,00 | E16: R$ 10.819,29 | F16: R$ 2.704,83/dia
A17: Gabriela | B17: R$ 45.000,00 | C17: R$ 13.834,16 | D17: R$ 40.500,00 | E17: R$ 26.665,84 | F17: R$ 6.666,46/dia | I17: 80% da meta
A18: Isabella | B18: R$ 50.000,00 | C18: R$ 12.418,78 | D18: R$ 45.000,00 | E18: R$ 32.581,22 | F18: R$ 8.145,31/dia | I18: Vendedor | J18: Meta | K18: Realizado | L18: 80% da meta | M18: Falta p/ 80% | N18: Precisa/dia (4 dias)
I19: Gustavo | J19: R$ 135.000,00 | K19: R$ 91.532,70 | L19: R$ 108.000,00 | M19: R$ 16.467,30 | N19: R$ 4.116,83/dia
I20: 90% da meta
I21: Vendedor | J21: Meta | K21: Realizado | L21: 90% da meta | M21: Falta p/ 90% | N21: Precisa/dia (4 dias)
I22: Gustavo | J22: R$ 135.000,00 | K22: R$ 91.532,70 | L22: R$ 121.500,00 | M22: R$ 29.967,30 | N22: R$ 7.491,83/dia
I26: 80% da meta
I27: Vendedor | J27: Meta | K27: Realizado | L27: 80% da meta | M27: Falta p/ 80% | N27: Precisa/dia (4 dias)
I28: Thalia | J28: R$ 75.000,00 | K28: R$ 39.760,68 | L28: R$ 60.000,00 | M28: R$ 20.239,32 | N28: R$ 5.059,83/dia
I29: 90% da meta
I30: Vendedor | J30: Meta | K30: Realizado | L30: 90% da meta | M30: Falta p/ 90% | N30: Precisa/dia (4 dias)
I31: Thalia | J31: R$ 75.000,00 | K31: R$ 39.760,68 | L31: R$ 67.500,00 | M31: R$ 27.739,32 | N31: R$ 6.934,83/dia
I35: 80% da meta
I36: Vendedor | J36: Meta | K36: Realizado | L36: 80% da meta | M36: Falta p/ 80% | N36: Precisa/dia (4 dias)
I37: Mirian | J37: R$ 65.000,00 | K37: R$ 47.680,71 | L37: R$ 52.000,00 | M37: R$ 4.319,29 | N37: R$ 1.079,83/dia
I38: 90% da meta
I39: Vendedor | J39: Meta | K39: Realizado | L39: 90% da meta | M39: Falta p/ 90% | N39: Precisa/dia (4 dias)
I40: Mirian | J40: R$ 65.000,00 | K40: R$ 47.680,71 | L40: R$ 58.500,00 | M40: R$ 10.819,29 | N40: R$ 2.704,83/dia
I44: 80% da meta
I45: Vendedor | J45: Meta | K45: Realizado | L45: 80% da meta | M45: Falta p/ 80% | N45: Precisa/dia (4 dias)
I46: Gabriela | J46: R$ 45.000,00 | K46: R$ 13.834,16 | L46: R$ 36.000,00 | M46: R$ 22.165,84 | N46: R$ 5.541,46/dia
I47: 90% da meta
I48: Vendedor | J48: Meta | K48: Realizado | L48: 90% da meta | M48: Falta p/ 90% | N48: Precisa/dia (4 dias)
I49: Gabriela | J49: R$ 45.000,00 | K49: R$ 13.834,16 | L49: R$ 40.500,00 | M49: R$ 26.665,84 | N49: R$ 6.666,46/dia
...

Sheet Compra - 09 
A1: Indicadores | B1: Leads | E1: Nº Vendas | H1: Faturamento | K1: Taxa Conversão | N1: Ticket Médio
A2: Data | B2: Realizado | C2: Meta | D2: Gap | E2: Realizado 2 | F2: Meta 2 | G2: Gap 2 | H2: Realizado 3 | I2: Meta 3 | J2: Gap 3 | K2: Realizado 4 | L2: Meta 4 | M2: Gap 4 | N2: Realizado 5 | O2: Meta 5 | P2: Gap 5
A3: 2025
A4: Setembro | B4: =B5+B36+B67 -> 3112 | C4: =C5+C36+C67 -> 1760 | D4: =D5+D36 -> 914 | E4: =E5+E36 -> 569 | F4: =F5+F36 -> 456 | G4: =G5+G36 -> 113 | H4: =H5+H36 -> 157072.11 | I4: =I5+I36 -> 114000 | J4: =J5+J36 -> 43072.11 | K4: =K5+K36 -> 0.5194821 | L4: =L5+L36 -> 0.6 | M4: =K4-L4 -> -0.080517895 | N4: =N5+N36 -> 540.75448 | O4: =O5+O36 -> 500 | P4: =P5+P36 -> 40.754479
A5: Thalia | B5: =SUM(B6:B35) -> 1743 | C5: =SUM(C6:C35) -> 1280 | D5: =SUM(D6:D35) -> 463 | E5: =SUM(E6:E35) -> 348 | F5: =SUM(F6:F35) -> 384 | G5: =SUM(G6:G35) -> -36 | H5: =SUM(H6:H35) -> 102935.03 | I5: =SUM(I6:I35) -> 96000 | J5: =SUM(J6:J35) -> 6935.03 | K5: =IFERROR(E5/B5,"") -> 0.19965577 | L5: 0.3 | M5: =K5-L5 -> -0.10034423 | N5: =IFERROR(H5/E5,"") -> 295.79032 | O5: 250 | P5: =N5-O5 -> 45.790316
A6: 45901 | B6: 52 | C6: 80 | D6: =B6-C6 -> -28 | E6: 13 | F6: =C6*30% -> 24 | G6: =E6-F6 -> -11 | H6: 3316.26 | I6: =F6*O6 -> 6000 | J6: =H6-I6 -> -2683.74 | K6: =IFERROR(E6/B6,"") -> 0.25 | L6: 0.3 | M6: =L6-K6 -> 0.05 | N6: =IFERROR(H6/E6,"") -> 255.09692 | O6: 250 | P6: =N6-O6 -> 5.0969231 | R6: Setembro
A7: 45902 | B7: 91 | C7: 80 | D7: =B7-C7 -> 11 | E7: 19 | F7: =C7*30% -> 24 | G7: =E7-F7 -> -5 | H7: 4072.51 | I7: =F7*O7 -> 6000 | J7: =H7-I7 -> -1927.49 | K7: =IFERROR(E7/B7,"") -> 0.20879121 | L7: 0.3 | M7: =L7-K7 -> 0.091208791 | N7: =IFERROR(H7/E7,"") -> 214.34263 | O7: 250 | P7: =N7-O7 -> -35.657368 | R7: Meta | S7: 110000
A8: 45903 | B8: 52 | C8: 80 | D8: =B8-C8 -> -28 | E8: 15 | F8: =C8*30% -> 24 | G8: =E8-F8 -> -9 | H8: 5709.56 | I8: =F8*O8 -> 6000 | J8: =H8-I8 -> -290.44 | K8: =IFERROR(E8/B8,"") -> 0.28846154 | L8: 0.3 | M8: =L8-K8 -> 0.011538462 | N8: =IFERROR(H8/E8,"") -> 380.63733 | O8: 250 | P8: =N8-O8 -> 130.63733 | R8: Meta x Dia | S8: =S7/30 -> 3666.6667
A9: 45904 | B9: 30 | C9: 80 | D9: =B9-C9 -> -50 | E9: 22 | F9: =C9*30% -> 24 | G9: =E9-F9 -> -2 | H9: 6197.98 | I9: =F9*O9 -> 6000 | J9: =H9-I9 -> 197.98 | K9: =IFERROR(E9/B9,"") -> 0.73333333 | L9: 0.3 | M9: =L9-K9 -> -0.43333333 | N9: =IFERROR(H9/E9,"") -> 281.72636 | O9: 250 | P9: =N9-O9 -> 31.726364 | R9: Meta x Dia Útil | S9: =S7/22 -> 5000
A10: 45905 | B10: 48 | C10: 80 | D10: =B10-C10 -> -32 | E10: 12 | F10: =C10*30% -> 24 | G10: =E10-F10 -> -12 | H10: 2511.67 | I10: =F10*O10 -> 6000 | J10: =H10-I10 -> -3488.33 | K10: =IFERROR(E10/B10,"") -> 0.25 | L10: 0.3 | M10: =L10-K10 -> 0.05 | N10: =IFERROR(H10/E10,"") -> 209.30583 | O10: 250 | P10: =N10-O10 -> -40.694167 | R10: Realizado | S10: =H5 -> 102935.03
